Workbook

Sheet Tie-Down Provision Workings
C1: Tie Down Provision Working Sheet (password: tiedown)
C3: Gravity Constant | D3: 9.81 | E3: m/s^2
C4: Longitudinal Design Force | D4: 4 | E4: G | F4: X
C5: Vertical Design Force | D5: 2 | E5: G | F5: Z
C6: Lateral Design Force | D6: 1.5 | E6: G | F6: Y
B8: Matrix 2 MCD(S) Tie-down Transportation Mode | P8: Fastener Installation Qty | T8: Longitudinal Fasteners Experienced Force (Individual) | W8: Longitudinal Fasteners Safety Factor (Idvl) | Z8: Vertical Fasteners Experienced Force (Individual) | AC8: Vertical Fasteners Safety Factor (Idvl) | AF8: Lateral Fasteners Experienced Force (Individual) | AI8: Lateral Fasteners Safety Factor (Idvl) | AL8: Fasteners Experienced Force (Individual) | AO8: Force Type | AR8: Fasteners Safety Factor (Idvl)
B9: No. | C9: Item | D9: Individual Weight (kg) | E9: Longitudinal (N) | F9: Vertical (N) | G9: Lateral (N) | H9: Fasterner Type | I9: Property Class | J9: Size | K9: X-Section Area | L9: Tensile Yield Strength (MPa) | M9: Shear Yield Strength (MPa) | N9: Tensile Yield Force (N) | O9: Shear Yield Force (N) | P9: Long. (pc) | Q9: Vert. (pc) | R9: Lateral (pc) | S9: Total (pc) | T9: Long. Tensile (N) | U9: Vert. Shear(N) | V9: Lateral Shear (N) | W9: Long. | X9: Vert. | Y9: Lateral | Z9: Long. Shear (N) | AA9: Vert. Tensile (N) | AB9: Lateral Shear (N) | AC9: Long. | AD9: Vert. | AE9: Lateral | AF9: Long. Shear (N) | AG9: Vert. Shear (N) | AH9: Lateral Tensile (N) | AI9: Long. | AJ9: Vert. | AK9: Lateral | AL9: Long. (N) | AM9: Vert. (N) | AN9: Lateral (N) | AO9: Long. | AP9: Vert. | AQ9: Lateral | AR9: Long. | AS9: Vert. | AT9: Lateral
B10: 1 | C10: Air-Con (IDU 1, 2) fastened to front wall | D10: 14 | E10: =D10*$D$3*$D$4 -> 549.36 | F10: =D10*$D$3*$D$5 -> 274.68 | G10: =D10*$D$3*$D$6 -> 206.01 | I10: 8.8 | J10: M6 | K10: =VLOOKUP(J10,'Fastener Data'!$E$3:$G$29,2,FALSE) -> 17.894 | L10: =VLOOKUP(I10,'Fastener Data'!$B$3:$C$18,2,FALSE) -> 640 | M10: =L10*0.5 -> 320 | N10: =K10*L10 -> 11452.16 | O10: =K10*M10 -> 5726.08 | P10: 6 | Q10: 0 | R10: 0 | S10: =SUM(P10:R10) -> 6 | T10: =IF(P10=0,"0",E10/P10) -> 91.56 | U10: =IF(P10=0,"0",F10/P10) -> 45.78 | V10: =IF(P10=0,"0",G10/P10) -> 34.335 | W10: =IF(T10="0","0",N10/T10) -> 125.0782 | X10: =IF(U10="0","0",O10/U10) -> 125.0782 | Y10: =IF(V10="0","0",O10/V10) -> 166.77093 | Z10: =IF(Q10=0,"0",E10/Q10) -> 0 | AA10: =IF(Q10=0,"0",F10/Q10) -> 0 | AB10: =IF(Q10=0,"0",G10/Q10) -> 0 | AC10: =IF(Z10="0","0",O10/Z10) -> 0 | AD10: =IF(AA10="0","0",N10/AA10) -> 0 | AE10: =IF(AB10="0","0",O10/AB10) -> 0 | AF10: =IF(R10=0,"0",E10/R10) -> 0 | AG10: =IF(R10=0,"0",F10/R10) -> 0 | AH10: =IF(R10=0,"0",G10/R10) -> 0 | AI10: =IF(AF10="0","0",O10/AF10) -> 0 | AJ10: =IF(AG10="0","0",O10/AG10) -> 0 | AK10: =IF(AH10="0","0",N10/AH10) -> 0 | AL10: =T10+Z10+AF10 -> 91.56 | AM10: =U10+AA10+AG10 -> 45.78 | AN10: =V10+AB10+AH10 -> 34.335 | AO10: =IF(I10="Strap","Tensile",IF(P10>0,"Tensile","Shear")) -> Tensile | AP10: =IF(I10="Strap","Tensile",IF(Q10>0,"Tensile","Shear")) -> Shear | AQ10: =IF(I10="Strap","Tensile",IF(R10>0,"Tensile","Shear")) -> Shear | AR10: =W10+AC10+AI10 -> 125.0782 | AS10: =X10+AD10+AJ10 -> 125.0782 | AT10: =Y10+AE10+AK10 -> 166.77093
B11: 2 | C11: Air-Con (IDU 3) fastened to right wall | D11: 14 | E11: =D11*$D$3*$D$4 -> 549.36 | F11: =D11*$D$3*$D$5 -> 274.68 | G11: =D11*$D$3*$D$6 -> 206.01 | I11: 8.8 | J11: M6 | K11: =VLOOKUP(J11,'Fastener Data'!$E$3:$G$29,2,FALSE) -> 17.894 | L11: =VLOOKUP(I11,'Fastener Data'!$B$3:$C$18,2,FALSE) -> 640 | M11: =L11*0.5 -> 320 | N11: =K11*L11 -> 11452.16 | O11: =K11*M11 -> 5726.08 | P11: 0 | Q11: 0 | R11: 6 | S11: =SUM(P11:R11) -> 6 | T11: =IF(P11=0,"0",E11/P11) -> 0 | U11: =IF(P11=0,"0",F11/P11) -> 0 | V11: =IF(P11=0,"0",G11/P11) -> 0 | W11: =IF(T11="0","0",N11/T11) -> 0 | X11: =IF(U11="0","0",O11/U11) -> 0 | Y11: =IF(V11="0","0",O11/V11) -> 0 | Z11: =IF(Q11=0,"0",E11/Q11) -> 0 | AA11: =IF(Q11=0,"0",F11/Q11) -> 0 | AB11: =IF(Q11=0,"0",G11/Q11) -> 0 | AC11: =IF(Z11="0","0",O11/Z11) -> 0 | AD11: =IF(AA11="0","0",N11/AA11) -> 0 | AE11: =IF(AB11="0","0",O11/AB11) -> 0 | AF11: =IF(R11=0,"0",E11/R11) -> 91.56 | AG11: =IF(R11=0,"0",F11/R11) -> 45.78 | AH11: =IF(R11=0,"0",G11/R11) -> 34.335 | AI11: =IF(AF11="0","0",O11/AF11) -> 62.5391 | AJ11: =IF(AG11="0","0",O11/AG11) -> 125.0782 | AK11: =IF(AH11="0","0",N11/AH11) -> 333.54187 | AL11: =T11+Z11+AF11 -> 91.56 | AM11: =U11+AA11+AG11 -> 45.78 | AN11: =V11+AB11+AH11 -> 34.335 | AO11: =IF(I11="Strap","Tensile",IF(P11>0,"Tensile","Shear")) -> Shear | AP11: =IF(I11="Strap","Tensile",IF(Q11>0,"Tensile","Shear")) -> Shear | AQ11: =IF(I11="Strap","Tensile",IF(R11>0,"Tensile","Shear")) -> Tensile | AR11: =W11+AC11+AI11 -> 62.5391 | AS11: =X11+AD11+AJ11 -> 125.0782 | AT11: =Y11+AE11+AK11 -> 333.54187
B12: 3 | C12: Air-Con (ODU 1, 2, 3) fastened to the top frame of the utility rack and the floor of the EM mast working platform | D12: 51 | E12: =D12*$D$3*$D$4 -> 2001.24 | F12: =D12*$D$3*$D$5 -> 1000.62 | G12: =D12*$D$3*$D$6 -> 750.465 | I12: 8.8 | J12: M10 | K12: =VLOOKUP(J12,'Fastener Data'!$E$3:$G$29,2,FALSE) -> 52.292 | L12: =VLOOKUP(I12,'Fastener Data'!$B$3:$C$18,2,FALSE) -> 640 | M12: =L12*0.5 -> 320 | N12: =K12*L12 -> 33466.88 | O12: =K12*M12 -> 16733.44 | P12: 0 | Q12: 4 | R12: 0 | S12: =SUM(P12:R12) -> 4 | T12: =IF(P12=0,"0",E12/P12) -> 0 | U12: =IF(P12=0,"0",F12/P12) -> 0 | V12: =IF(P12=0,"0",G12/P12) -> 0 | W12: =IF(T12="0","0",N12/T12) -> 0 | X12: =IF(U12="0","0",O12/U12) -> 0 | Y12: =IF(V12="0","0",O12/V12) -> 0 | Z12: =IF(Q12=0,"0",E12/Q12) -> 500.31 | AA12: =IF(Q12=0,"0",F12/Q12) -> 250.155 | AB12: =IF(Q12=0,"0",G12/Q12) -> 187.61625 | AC12: =IF(Z12="0","0",O12/Z12) -> 33.446143 | AD12: =IF(AA12="0","0",N12/AA12) -> 133.78457 | AE12: =IF(AB12="0","0",O12/AB12) -> 89.189716 | AF12: =IF(R12=0,"0",E12/R12) -> 0 | AG12: =IF(R12=0,"0",F12/R12) -> 0 | AH12: =IF(R12=0,"0",G12/R12) -> 0 | AI12: =IF(AF12="0","0",O12/AF12) -> 0 | AJ12: =IF(AG12="0","0",O12/AG12) -> 0 | AK12: =IF(AH12="0","0",N12/AH12) -> 0 | AL12: =T12+Z12+AF12 -> 500.31 | AM12: =U12+AA12+AG12 -> 250.155 | AN12: =V12+AB12+AH12 -> 187.61625 | AO12: =IF(I12="Strap","Tensile",IF(P12>0,"Tensile","Shear")) -> Shear | AP12: =IF(I12="Strap","Tensile",IF(Q12>0,"Tensile","Shear")) -> Tensile | AQ12: =IF(I12="Strap","Tensile",IF(R12>0,"Tensile","Shear")) -> Shear | AR12: =W12+AC12+AI12 -> 33.446143 | AS12: =X12+AD12+AJ12 -> 133.78457 | AT12: =Y12+AE12+AK12 -> 89.189716
B13: 4 | C13: Foldable Table fastened to right side wall | D13: 10 | E13: =D13*$D$3*$D$4 -> 392.4 | F13: =D13*$D$3*$D$5 -> 196.2 | G13: =D13*$D$3*$D$6 -> 147.15 | I13: 8.8 | J13: M6 | K13: =VLOOKUP(J13,'Fastener Data'!$E$3:$G$29,2,FALSE) -> 17.894 | L13: =VLOOKUP(I13,'Fastener Data'!$B$3:$C$18,2,FALSE) -> 640 | M13: =L13*0.5 -> 320 | N13: =K13*L13 -> 11452.16 | O13: =K13*M13 -> 5726.08 | P13: 0 | Q13: 0 | R13: 6 | S13: =SUM(P13:R13) -> 6 | T13: =IF(P13=0,"0",E13/P13) -> 0 | U13: =IF(P13=0,"0",F13/P13) -> 0 | V13: =IF(P13=0,"0",G13/P13) -> 0 | W13: =IF(T13="0","0",N13/T13) -> 0 | X13: =IF(U13="0","0",O13/U13) -> 0 | Y13: =IF(V13="0","0",O13/V13) -> 0 | Z13: =IF(Q13=0,"0",E13/Q13) -> 0 | AA13: =IF(Q13=0,"0",F13/Q13) -> 0 | AB13: =IF(Q13=0,"0",G13/Q13) -> 0 | AC13: =IF(Z13="0","0",O13/Z13) -> 0 | AD13: =IF(AA13="0","0",N13/AA13) -> 0 | AE13: =IF(AB13="0","0",O13/AB13) -> 0 | AF13: =IF(R13=0,"0",E13/R13) -> 65.4 | AG13: =IF(R13=0,"0",F13/R13) -> 32.7 | AH13: =IF(R13=0,"0",G13/R13) -> 24.525 | AI13: =IF(AF13="0","0",O13/AF13) -> 87.55474 | AJ13: =IF(AG13="0","0",O13/AG13) -> 175.10948 | AK13: =IF(AH13="0","0",N13/AH13) -> 466.95861 | AL13: =T13+Z13+AF13 -> 65.4 | AM13: =U13+AA13+AG13 -> 32.7 | AN13: =V13+AB13+AH13 -> 24.525 | AO13: =IF(I13="Strap","Tensile",IF(P13>0,"Tensile","Shear")) -> Shear | AP13: =IF(I13="Strap","Tensile",IF(Q13>0,"Tensile","Shear")) -> Shear | AQ13: =IF(I13="Strap","Tensile",IF(R13>0,"Tensile","Shear")) -> Tensile | AR13: =W13+AC13+AI13 -> 87.55474 | AS13: =X13+AD13+AJ13 -> 175.10948 | AT13: =Y13+AE13+AK13 -> 466.95861
B14: 5 | C14: Foldable Chairs (3x) strap to the rear wall | D14: 13.5 | E14: =D14*$D$3*$D$4 -> 529.74 | F14: =D14*$D$3*$D$5 -> 264.87 | G14: =D14*$D$3*$D$6 -> 198.6525 | I14: Camlock Strap (1") | J14: Camlock Strap (1") | K14: =VLOOKUP(J14,'Fastener Data'!$E$3:$G$29,2,FALSE) -> 1 | L14: =VLOOKUP(I14,'Fastener Data'!$B$3:$C$18,2,FALSE) -> 2500 | M14: =L14 -> 2500 | N14: =K14*L14 -> 2500 | O14: =K14*M14 -> 2500 | P14: 1 | Q14: 0 | R14: 0 | S14: =SUM(P14:R14) -> 1 | T14: =IF(P14=0,"0",E14/P14) -> 529.74 | U14: =IF(P14=0,"0",F14/P14) -> 264.87 | V14: =IF(P14=0,"0",G14/P14) -> 198.6525 | W14: =IF(T14="0","0",N14/T14) -> 4.7192963 | X14: =IF(U14="0","0",O14/U14) -> 9.4385925 | Y14: =IF(V14="0","0",O14/V14) -> 12.58479 | Z14: =IF(Q14=0,"0",E14/Q14) -> 0 | AA14: =IF(Q14=0,"0",F14/Q14) -> 0 | AB14: =IF(Q14=0,"0",G14/Q14) -> 0 | AC14: =IF(Z14="0","0",O14/Z14) -> 0 | AD14: =IF(AA14="0","0",N14/AA14) -> 0 | AE14: =IF(AB14="0","0",O14/AB14) -> 0 | AF14: =IF(R14=0,"0",E14/R14) -> 0 | AG14: =IF(R14=0,"0",F14/R14) -> 0 | AH14: =IF(R14=0,"0",G14/R14) -> 0 | AI14: =IF(AF14="0","0",O14/AF14) -> 0 | AJ14: =IF(AG14="0","0",O14/AG14) -> 0 | AK14: =IF(AH14="0","0",N14/AH14) -> 0 | AL14: =T14+Z14+AF14 -> 529.74 | AM14: =U14+AA14+AG14 -> 264.87 | AN14: =V14+AB14+AH14 -> 198.6525 | AO14: =IF(I14="Strap","Tensile",IF(P14>0,"Tensile","Shear")) -> Tensile | AP14: =IF(I14="Strap","Tensile",IF(Q14>0,"Tensile","Shear")) -> Shear | AQ14: =IF(I14="Strap","Tensile",IF(R14>0,"Tensile","Shear")) -> Shear | AR14: =W14+AC14+AI14 -> 4.7192963 | AS14: =X14+AD14+AJ14 -> 9.4385925 | AT14: =Y14+AE14+AK14 -> 12.58479
B15: 6 | C15: First Aid Kit strap to the rear wall | D15: 2 | E15: =D15*$D$3*$D$4 -> 78.48 | F15: =D15*$D$3*$D$5 -> 39.24 | G15: =D15*$D$3*$D$6 -> 29.43 | I15: Camlock Strap (1") | J15: Camlock Strap (1") | K15: =VLOOKUP(J15,'Fastener Data'!$E$3:$G$29,2,FALSE) -> 1 | L15: =VLOOKUP(I15,'Fastener Data'!$B$3:$C$18,2,FALSE) -> 2500 | M15: =L15 -> 2500 | N15: =K15*L15 -> 2500 | O15: =K15*M15 -> 2500 | P15: 1 | Q15: 0 | R15: 0 | S15: =SUM(P15:R15) -> 1 | T15: =IF(P15=0,"0",E15/P15) -> 78.48 | U15: =IF(P15=0,"0",F15/P15) -> 39.24 | V15: =IF(P15=0,"0",G15/P15) -> 29.43 | W15: =IF(T15="0","0",N15/T15) -> 31.85525 | X15: =IF(U15="0","0",O15/U15) -> 63.710499 | Y15: =IF(V15="0","0",O15/V15) -> 84.947333 | Z15: =IF(Q15=0,"0",E15/Q15) -> 0 | AA15: =IF(Q15=0,"0",F15/Q15) -> 0 | AB15: =IF(Q15=0,"0",G15/Q15) -> 0 | AC15: =IF(Z15="0","0",O15/Z15) -> 0 | AD15: =IF(AA15="0","0",N15/AA15) -> 0 | AE15: =IF(AB15="0","0",O15/AB15) -> 0 | AF15: =IF(R15=0,"0",E15/R15) -> 0 | AG15: =IF(R15=0,"0",F15/R15) -> 0 | AH15: =IF(R15=0,"0",G15/R15) -> 0 | AI15: =IF(AF15="0","0",O15/AF15) -> 0 | AJ15: =IF(AG15="0","0",O15/AG15) -> 0 | AK15: =IF(AH15="0","0",N15/AH15) -> 0 | AL15: =T15+Z15+AF15 -> 78.48 | AM15: =U15+AA15+AG15 -> 39.24 | AN15: =V15+AB15+AH15 -> 29.43 | AO15: =IF(I15="Strap","Tensile",IF(P15>0,"Tensile","Shear")) -> Tensile | AP15: =IF(I15="Strap","Tensile",IF(Q15>0,"Tensile","Shear")) -> Shear | AQ15: =IF(I15="Strap","Tensile",IF(R15>0,"Tensile","Shear")) -> Shear | AR15: =W15+AC15+AI15 -> 31.85525 | AS15: =X15+AD15+AJ15 -> 63.710499 | AT15: =Y15+AE15+AK15 -> 84.947333
B16: 7 | C16: CO Detector fastenered to the rear wall | D16: 1 | E16: =D16*$D$3*$D$4 -> 39.24 | F16: =D16*$D$3*$D$5 -> 19.62 | G16: =D16*$D$3*$D$6 -> 14.715 | I16: Camlock Strap (1") | J16: Camlock Strap (1") | K16: =VLOOKUP(J16,'Fastener Data'!$E$3:$G$29,2,FALSE) -> 1 | L16: =VLOOKUP(I16,'Fastener Data'!$B$3:$C$18,2,FALSE) -> 2500 | M16: =L16 -> 2500 | N16: =K16*L16 -> 2500 | O16: =K16*M16 -> 2500 | P16: 1 | Q16: 0 | R16: 0 | S16: =SUM(P16:R16) -> 1 | T16: =IF(P16=0,"0",E16/P16) -> 39.24 | U16: =IF(P16=0,"0",F16/P16) -> 19.62 | V16: =IF(P16=0,"0",G16/P16) -> 14.715 | W16: =IF(T16="0","0",N16/T16) -> 63.710499 | X16: =IF(U16="0","0",O16/U16) -> 127.421 | Y16: =IF(V16="0","0",O16/V16) -> 169.89467 | Z16: =IF(Q16=0,"0",E16/Q16) -> 0 | AA16: =IF(Q16=0,"0",F16/Q16) -> 0 | AB16: =IF(Q16=0,"0",G16/Q16) -> 0 | AC16: =IF(Z16="0","0",O16/Z16) -> 0 | AD16: =IF(AA16="0","0",N16/AA16) -> 0 | AE16: =IF(AB16="0","0",O16/AB16) -> 0 | AF16: =IF(R16=0,"0",E16/R16) -> 0 | AG16: =IF(R16=0,"0",F16/R16) -> 0 | AH16: =IF(R16=0,"0",G16/R16) -> 0 | AI16: =IF(AF16="0","0",O16/AF16) -> 0 | AJ16: =IF(AG16="0","0",O16/AG16) -> 0 | AK16: =IF(AH16="0","0",N16/AH16) -> 0 | AL16: =T16+Z16+AF16 -> 39.24 | AM16: =U16+AA16+AG16 -> 19.62 | AN16: =V16+AB16+AH16 -> 14.715 | AO16: =IF(I16="Strap","Tensile",IF(P16>0,"Tensile","Shear")) -> Tensile | AP16: =IF(I16="Strap","Tensile",IF(Q16>0,"Tensile","Shear")) -> Shear | AQ16: =IF(I16="Strap","Tensile",IF(R16>0,"Tensile","Shear")) -> Shear | AR16: =W16+AC16+AI16 -> 63.710499 | AS16: =X16+AD16+AJ16 -> 127.421 | AT16: =Y16+AE16+AK16 -> 169.89467
B17: 8 | C17: Fire Extinguisher fastened to the rear wall | D17: 4 | E17: =D17*$D$3*$D$4 -> 156.96 | F17: =D17*$D$3*$D$5 -> 78.48 | G17: =D17*$D$3*$D$6 -> 58.86 | H17: Allan | I17: 8.8 | J17: M6 | K17: =VLOOKUP(J17,'Fastener Data'!$E$3:$G$29,2,FALSE) -> 17.894 | L17: =VLOOKUP(I17,'Fastener Data'!$B$3:$C$18,2,FALSE) -> 640 | M17: =L17*0.5 -> 320 | N17: =K17*L17 -> 11452.16 | O17: =K17*M17 -> 5726.08 | P17: 3 | Q17: 0 | R17: 0 | S17: =SUM(P17:R17) -> 3 | T17: =IF(P17=0,"0",E17/P17) -> 52.32 | U17: =IF(P17=0,"0",F17/P17) -> 26.16 | V17: =IF(P17=0,"0",G17/P17) -> 19.62 | W17: =IF(T17="0","0",N17/T17) -> 218.88685 | X17: =IF(U17="0","0",O17/U17) -> 218.88685 | Y17: =IF(V17="0","0",O17/V17) -> 291.84913 | Z17: =IF(Q17=0,"0",E17/Q17) -> 0 | AA17: =IF(Q17=0,"0",F17/Q17) -> 0 | AB17: =IF(Q17=0,"0",G17/Q17) -> 0 | AC17: =IF(Z17="0","0",O17/Z17) -> 0 | AD17: =IF(AA17="0","0",N17/AA17) -> 0 | AE17: =IF(AB17="0","0",O17/AB17) -> 0 | AF17: =IF(R17=0,"0",E17/R17) -> 0 | AG17: =IF(R17=0,"0",F17/R17) -> 0 | AH17: =IF(R17=0,"0",G17/R17) -> 0 | AI17: =IF(AF17="0","0",O17/AF17) -> 0 | AJ17: =IF(AG17="0","0",O17/AG17) -> 0 | AK17: =IF(AH17="0","0",N17/AH17) -> 0 | AL17: =T17+Z17+AF17 -> 52.32 | AM17: =U17+AA17+AG17 -> 26.16 | AN17: =V17+AB17+AH17 -> 19.62 | AO17: =IF(I17="Strap","Tensile",IF(P17>0,"Tensile","Shear")) -> Tensile | AP17: =IF(I17="Strap","Tensile",IF(Q17>0,"Tensile","Shear")) -> Shear | AQ17: =IF(I17="Strap","Tensile",IF(R17>0,"Tensile","Shear")) -> Shear | AR17: =W17+AC17+AI17 -> 218.88685 | AS17: =X17+AD17+AJ17 -> 218.88685 | AT17: =Y17+AE17+AK17 -> 291.84913
B18: 9 | C18: Safety Harness with Bag strap to the rear wall | D18: 10 | E18: =D18*$D$3*$D$4 -> 392.4 | F18: =D18*$D$3*$D$5 -> 196.2 | G18: =D18*$D$3*$D$6 -> 147.15 | I18: Camlock Strap (1") | J18: Camlock Strap (1") | K18: 1 | L18: =VLOOKUP(I18,'Fastener Data'!$B$3:$C$18,2,FALSE) -> 2500 | M18: =L18 -> 2500 | N18: =K18*L18 -> 2500 | O18: =K18*M18 -> 2500 | P18: 2 | Q18: 0 | R18: 0 | S18: =SUM(P18:R18) -> 2 | T18: =IF(P18=0,"0",E18/P18) -> 196.2 | U18: =IF(P18=0,"0",F18/P18) -> 98.1 | V18: =IF(P18=0,"0",G18/P18) -> 73.575 | W18: =IF(T18="0","0",N18/T18) -> 12.7421 | X18: =IF(U18="0","0",O18/U18) -> 25.4842 | Y18: =IF(V18="0","0",O18/V18) -> 33.978933 | Z18: =IF(Q18=0,"0",E18/Q18) -> 0 | AA18: =IF(Q18=0,"0",F18/Q18) -> 0 | AB18: =IF(Q18=0,"0",G18/Q18) -> 0 | AC18: =IF(Z18="0","0",O18/Z18) -> 0 | AD18: =IF(AA18="0","0",N18/AA18) -> 0 | AE18: =IF(AB18="0","0",O18/AB18) -> 0 | AF18: =IF(R18=0,"0",E18/R18) -> 0 | AG18: =IF(R18=0,"0",F18/R18) -> 0 | AH18: =IF(R18=0,"0",G18/R18) -> 0 | AI18: =IF(AF18="0","0",O18/AF18) -> 0 | AJ18: =IF(AG18="0","0",O18/AG18) -> 0 | AK18: =IF(AH18="0","0",N18/AH18) -> 0 | AL18: =T18+Z18+AF18 -> 196.2 | AM18: =U18+AA18+AG18 -> 98.1 | AN18: =V18+AB18+AH18 -> 73.575 | AO18: =IF(I18="Strap","Tensile",IF(P18>0,"Tensile","Shear")) -> Tensile | AP18: =IF(I18="Strap","Tensile",IF(Q18>0,"Tensile","Shear")) -> Shear | AQ18: =IF(I18="Strap","Tensile",IF(R18>0,"Tensile","Shear")) -> Shear | AR18: =W18+AC18+AI18 -> 12.7421 | AS18: =X18+AD18+AJ18 -> 25.4842 | AT18: =Y18+AE18+AK18 -> 33.978933
B19: 10 | C19: DCC Touch Panel fastened to the rear wall | D19: 10 | E19: =D19*$D$3*$D$4 -> 392.4 | F19: =D19*$D$3*$D$5 -> 196.2 | G19: =D19*$D$3*$D$6 -> 147.15 | I19: 8.8 | J19: M6 | K19: =VLOOKUP(J19,'Fastener Data'!$E$3:$G$29,2,FALSE) -> 17.894 | L19: =VLOOKUP(I19,'Fastener Data'!$B$3:$C$18,2,FALSE) -> 640 | M19: =L19*0.5 -> 320 | N19: =K19*L19 -> 11452.16 | O19: =K19*M19 -> 5726.08 | P19: 4 | Q19: 0 | R19: 0 | S19: =SUM(P19:R19) -> 4 | T19: =IF(P19=0,"0",E19/P19) -> 98.1 | U19: =IF(P19=0,"0",F19/P19) -> 49.05 | V19: =IF(P19=0,"0",G19/P19) -> 36.7875 | W19: =IF(T19="0","0",N19/T19) -> 116.73965 | X19: =IF(U19="0","0",O19/U19) -> 116.73965 | Y19: =IF(V19="0","0",O19/V19) -> 155.65287 | Z19: =IF(Q19=0,"0",E19/Q19) -> 0 | AA19: =IF(Q19=0,"0",F19/Q19) -> 0 | AB19: =IF(Q19=0,"0",G19/Q19) -> 0 | AC19: =IF(Z19="0","0",O19/Z19) -> 0 | AD19: =IF(AA19="0","0",N19/AA19) -> 0 | AE19: =IF(AB19="0","0",O19/AB19) -> 0 | AF19: =IF(R19=0,"0",E19/R19) -> 0 | AG19: =IF(R19=0,"0",F19/R19) -> 0 | AH19: =IF(R19=0,"0",G19/R19) -> 0 | AI19: =IF(AF19="0","0",O19/AF19) -> 0 | AJ19: =IF(AG19="0","0",O19/AG19) -> 0 | AK19: =IF(AH19="0","0",N19/AH19) -> 0 | AL19: =T19+Z19+AF19 -> 98.1 | AM19: =U19+AA19+AG19 -> 49.05 | AN19: =V19+AB19+AH19 -> 36.7875 | AO19: =IF(I19="Strap","Tensile",IF(P19>0,"Tensile","Shear")) -> Tensile | AP19: =IF(I19="Strap","Tensile",IF(Q19>0,"Tensile","Shear")) -> Shear | AQ19: =IF(I19="Strap","Tensile",IF(R19>0,"Tensile","Shear")) -> Shear | AR19: =W19+AC19+AI19 -> 116.73965 | AS19: =X19+AD19+AJ19 -> 116.73965 | AT19: =Y19+AE19+AK19 -> 155.65287
B20: 11 | C20: Generator fastened to the base structure at Outdoor Facilities | D20: 1269 | E20: =D20*$D$3*$D$4 -> 49795.56 | F20: =D20*$D$3*$D$5 -> 24897.78 | G20: =D20*$D$3*$D$6 -> 18673.335 | I20: 8.8 | J20: M12 | K20: =VLOOKUP(J20,'Fastener Data'!$E$3:$G$29,2,FALSE) -> 76.247 | L20: =VLOOKUP(I20,'Fastener Data'!$B$3:$C$18,2,FALSE) -> 640 | M20: =L20*0.5 -> 320 | N20: =K20*L20 -> 48798.08 | O20: =K20*M20 -> 24399.04 | P20: 0 | Q20: 10 | R20: 0 | S20: =SUM(P20:R20) -> 10 | T20: =IF(P20=0,"0",E20/P20) -> 0 | U20: =IF(P20=0,"0",F20/P20) -> 0 | V20: =IF(P20=0,"0",G20/P20) -> 0 | W20: =IF(T20="0","0",N20/T20) -> 0 | X20: =IF(U20="0","0",O20/U20) -> 0 | Y20: =IF(V20="0","0",O20/V20) -> 0 | Z20: =IF(Q20=0,"0",E20/Q20) -> 4979.556 | AA20: =IF(Q20=0,"0",F20/Q20) -> 2489.778 | AB20: =IF(Q20=0,"0",G20/Q20) -> 1867.3335 | AC20: =IF(Z20="0","0",O20/Z20) -> 4.8998425 | AD20: =IF(AA20="0","0",N20/AA20) -> 19.59937 | AE20: =IF(AB20="0","0",O20/AB20) -> 13.066247 | AF20: =IF(R20=0,"0",E20/R20) -> 0 | AG20: =IF(R20=0,"0",F20/R20) -> 0 | AH20: =IF(R20=0,"0",G20/R20) -> 0 | AI20: =IF(AF20="0","0",O20/AF20) -> 0 | AJ20: =IF(AG20="0","0",O20/AG20) -> 0 | AK20: =IF(AH20="0","0",N20/AH20) -> 0 | AL20: =T20+Z20+AF20 -> 4979.556 | AM20: =U20+AA20+AG20 -> 2489.778 | AN20: =V20+AB20+AH20 -> 1867.3335 | AO20: =IF(I20="Strap","Tensile",IF(P20>0,"Tensile","Shear")) -> Shear | AP20: =IF(I20="Strap","Tensile",IF(Q20>0,"Tensile","Shear")) -> Tensile | AQ20: =IF(I20="Strap","Tensile",IF(R20>0,"Tensile","Shear")) -> Shear | AR20: =W20+AC20+AI20 -> 4.8998425 | AS20: =X20+AD20+AJ20 -> 19.59937 | AT20: =Y20+AE20+AK20 -> 13.066247
B21: 12 | C21: Outdoor Facilities Ladder latched in the Outdoor Facilities Ladder Storage | D21: 20 | E21: =D21*$D$3*$D$4 -> 784.8 | F21: =D21*$D$3*$D$5 -> 392.4 | G21: =D21*$D$3*$D$6 -> 294.3 | I21: Spring Latch | J21: Spring Latch | K21: =VLOOKUP(J21,'Fastener Data'!$E$3:$G$29,2,FALSE) -> 113.09734 | L21: =VLOOKUP(I21,'Fastener Data'!$B$3:$C$18,2,FALSE) -> 165 | M21: =L21*0.5 -> 82.5 | N21: =K21*L21 -> 18661.06 | O21: =K21*M21 -> 9330.5302 | P21: 1 | Q21: 0 | R21: 0 | S21: =SUM(P21:R21) -> 1 | T21: =IF(P21=0,"0",E21/P21) -> 784.8 | U21: =IF(P21=0,"0",F21/P21) -> 392.4 | V21: =IF(P21=0,"0",G21/P21) -> 294.3 | W21: =IF(T21="0","0",N21/T21) -> 23.77811 | X21: =IF(U21="0","0",O21/U21) -> 23.77811 | Y21: =IF(V21="0","0",O21/V21) -> 31.704146 | Z21: =IF(Q21=0,"0",E21/Q21) -> 0 | AA21: =IF(Q21=0,"0",F21/Q21) -> 0 | AB21: =IF(Q21=0,"0",G21/Q21) -> 0 | AC21: =IF(Z21="0","0",O21/Z21) -> 0 | AD21: =IF(AA21="0","0",N21/AA21) -> 0 | AE21: =IF(AB21="0","0",O21/AB21) -> 0 | AF21: =IF(R21=0,"0",E21/R21) -> 0 | AG21: =IF(R21=0,"0",F21/R21) -> 0 | AH21: =IF(R21=0,"0",G21/R21) -> 0 | AI21: =IF(AF21="0","0",O21/AF21) -> 0 | AJ21: =IF(AG21="0","0",O21/AG21) -> 0 | AK21: =IF(AH21="0","0",N21/AH21) -> 0 | AL21: =T21+Z21+AF21 -> 784.8 | AM21: =U21+AA21+AG21 -> 392.4 | AN21: =V21+AB21+AH21 -> 294.3 | AO21: =IF(I21="Strap","Tensile",IF(P21>0,"Tensile","Shear")) -> Tensile | AP21: =IF(I21="Strap","Tensile",IF(Q21>0,"Tensile","Shear")) -> Shear | AQ21: =IF(I21="Strap","Tensile",IF(R21>0,"Tensile","Shear")) -> Shear | AR21: =W21+AC21+AI21 -> 23.77811 | AS21: =X21+AD21+AJ21 -> 23.77811 | AT21: =Y21+AE21+AK21 -> 31.704146
B22: 13 | C22: Outdoor Facilities Ladder Storage fastened to the front bottom beam at Outdoor Facilities Area | D22: 35 | E22: =D22*$D$3*$D$4 -> 1373.4 | F22: =D22*$D$3*$D$5 -> 686.7 | G22: =D22*$D$3*$D$6 -> 515.025 | I22: 8.8 | J22: M8 | K22: =VLOOKUP(J22,'Fastener Data'!$E$3:$G$29,2,FALSE) -> 32.841 | L22: =VLOOKUP(I22,'Fastener Data'!$B$3:$C$18,2,FALSE) -> 640 | M22: =L22*0.5 -> 320 | N22: =K22*L22 -> 21018.24 | O22: =K22*M22 -> 10509.12 | P22: 12 | Q22: 0 | R22: 0 | S22: =SUM(P22:R22) -> 12 | T22: =IF(P22=0,"0",E22/P22) -> 114.45 | U22: =IF(P22=0,"0",F22/P22) -> 57.225 | V22: =IF(P22=0,"0",G22/P22) -> 42.91875 | W22: =IF(T22="0","0",N22/T22) -> 183.64561 | X22: =IF(U22="0","0",O22/U22) -> 183.64561 | Y22: =IF(V22="0","0",O22/V22) -> 244.86081 | Z22: =IF(Q22=0,"0",E22/Q22) -> 0 | AA22: =IF(Q22=0,"0",F22/Q22) -> 0 | AB22: =IF(Q22=0,"0",G22/Q22) -> 0 | AC22: =IF(Z22="0","0",O22/Z22) -> 0 | AD22: =IF(AA22="0","0",N22/AA22) -> 0 | AE22: =IF(AB22="0","0",O22/AB22) -> 0 | AF22: =IF(R22=0,"0",E22/R22) -> 0 | AG22: =IF(R22=0,"0",F22/R22) -> 0 | AH22: =IF(R22=0,"0",G22/R22) -> 0 | AI22: =IF(AF22="0","0",O22/AF22) -> 0 | AJ22: =IF(AG22="0","0",O22/AG22) -> 0 | AK22: =IF(AH22="0","0",N22/AH22) -> 0 | AL22: =T22+Z22+AF22 -> 114.45 | AM22: =U22+AA22+AG22 -> 57.225 | AN22: =V22+AB22+AH22 -> 42.91875 | AO22: =IF(I22="Strap","Tensile",IF(P22>0,"Tensile","Shear")) -> Tensile | AP22: =IF(I22="Strap","Tensile",IF(Q22>0,"Tensile","Shear")) -> Shear | AQ22: =IF(I22="Strap","Tensile",IF(R22>0,"Tensile","Shear")) -> Shear | AR22: =W22+AC22+AI22 -> 183.64561 | AS22: =X22+AD22+AJ22 -> 183.64561 | AT22: =Y22+AE22+AK22 -> 244.86081
B23: 14 | C23: Rear Door Ladder latched in the Rear Door Ladder Storage | D23: 20 | E23: =D23*$D$3*$D$4 -> 784.8 | F23: =D23*$D$3*$D$5 -> 392.4 | G23: =D23*$D$3*$D$6 -> 294.3 | I23: Spring Latch | J23: Spring Latch | K23: =VLOOKUP(J23,'Fastener Data'!$E$3:$G$29,2,FALSE) -> 113.09734 | L23: =VLOOKUP(I23,'Fastener Data'!$B$3:$C$18,2,FALSE) -> 165 | M23: =L23*0.5 -> 82.5 | N23: =K23*L23 -> 18661.06 | O23: =K23*M23 -> 9330.5302 | P23: 1 | Q23: 0 | R23: 0 | S23: =SUM(P23:R23) -> 1 | T23: =IF(P23=0,"0",E23/P23) -> 784.8 | U23: =IF(P23=0,"0",F23/P23) -> 392.4 | V23: =IF(P23=0,"0",G23/P23) -> 294.3 | W23: =IF(T23="0","0",N23/T23) -> 23.77811 | X23: =IF(U23="0","0",O23/U23) -> 23.77811 | Y23: =IF(V23="0","0",O23/V23) -> 31.704146 | Z23: =IF(Q23=0,"0",E23/Q23) -> 0 | AA23: =IF(Q23=0,"0",F23/Q23) -> 0 | AB23: =IF(Q23=0,"0",G23/Q23) -> 0 | AC23: =IF(Z23="0","0",O23/Z23) -> 0 | AD23: =IF(AA23="0","0",N23/AA23) -> 0 | AE23: =IF(AB23="0","0",O23/AB23) -> 0 | AF23: =IF(R23=0,"0",E23/R23) -> 0 | AG23: =IF(R23=0,"0",F23/R23) -> 0 | AH23: =IF(R23=0,"0",G23/R23) -> 0 | AI23: =IF(AF23="0","0",O23/AF23) -> 0 | AJ23: =IF(AG23="0","0",O23/AG23) -> 0 | AK23: =IF(AH23="0","0",N23/AH23) -> 0 | AL23: =T23+Z23+AF23 -> 784.8 | AM23: =U23+AA23+AG23 -> 392.4 | AN23: =V23+AB23+AH23 -> 294.3 | AO23: =IF(I23="Strap","Tensile",IF(P23>0,"Tensile","Shear")) -> Tensile | AP23: =IF(I23="Strap","Tensile",IF(Q23>0,"Tensile","Shear")) -> Shear | AQ23: =IF(I23="Strap","Tensile",IF(R23>0,"Tensile","Shear")) -> Shear | AR23: =W23+AC23+AI23 -> 23.77811 | AS23: =X23+AD23+AJ23 -> 23.77811 | AT23: =Y23+AE23+AK23 -> 31.704146
B24: 15 | C24: Rear Door Ladder Storage w/ platform fastened to the rear bottom beam | D24: 45 | E24: =D24*$D$3*$D$4 -> 1765.8 | F24: =D24*$D$3*$D$5 -> 882.9 | G24: =D24*$D$3*$D$6 -> 662.175 | I24: 8.8 | J24: M6 | K24: =VLOOKUP(J24,'Fastener Data'!$E$3:$G$29,2,FALSE) -> 17.894 | L24: =VLOOKUP(I24,'Fastener Data'!$B$3:$C$18,2,FALSE) -> 640 | M24: =L24*0.5 -> 320 | N24: =K24*L24 -> 11452.16 | O24: =K24*M24 -> 5726.08 | P24: 20 | Q24: 0 | R24: 0 | S24: =SUM(P24:R24) -> 20 | T24: =IF(P24=0,"0",E24/P24) -> 88.29 | U24: =IF(P24=0,"0",F24/P24) -> 44.145 | V24: =IF(P24=0,"0",G24/P24) -> 33.10875 | W24: =IF(T24="0","0",N24/T24) -> 129.71073 | X24: =IF(U24="0","0",O24/U24) -> 129.71073 | Y24: =IF(V24="0","0",O24/V24) -> 172.94763 | Z24: =IF(Q24=0,"0",E24/Q24) -> 0 | AA24: =IF(Q24=0,"0",F24/Q24) -> 0 | AB24: =IF(Q24=0,"0",G24/Q24) -> 0 | AC24: =IF(Z24="0","0",O24/Z24) -> 0 | AD24: =IF(AA24="0","0",N24/AA24) -> 0 | AE24: =IF(AB24="0","0",O24/AB24) -> 0 | AF24: =IF(R24=0,"0",E24/R24) -> 0 | AG24: =IF(R24=0,"0",F24/R24) -> 0 | AH24: =IF(R24=0,"0",G24/R24) -> 0 | AI24: =IF(AF24="0","0",O24/AF24) -> 0 | AJ24: =IF(AG24="0","0",O24/AG24) -> 0 | AK24: =IF(AH24="0","0",N24/AH24) -> 0 | AL24: =T24+Z24+AF24 -> 88.29 | AM24: =U24+AA24+AG24 -> 44.145 | AN24: =V24+AB24+AH24 -> 33.10875 | AO24: =IF(I24="Strap","Tensile",IF(P24>0,"Tensile","Shear")) -> Tensile | AP24: =IF(I24="Strap","Tensile",IF(Q24>0,"Tensile","Shear")) -> Shear | AQ24: =IF(I24="Strap","Tensile",IF(R24>0,"Tensile","Shear")) -> Shear | AR24: =W24+AC24+AI24 -> 129.71073 | AS24: =X24+AD24+AJ24 -> 129.71073 | AT24: =Y24+AE24+AK24 -> 172.94763
B25: 16 | C25: Rear Roof Access Ladder fastened to rear wall | D25: 5 | E25: =D25*$D$3*$D$4 -> 196.2 | F25: =D25*$D$3*$D$5 -> 98.1 | G25: =D25*$D$3*$D$6 -> 73.575 | I25: 8.8 | J25: M6 | K25: =VLOOKUP(J25,'Fastener Data'!$E$3:$G$29,2,FALSE) -> 17.894 | L25: =VLOOKUP(I25,'Fastener Data'!$B$3:$C$18,2,FALSE) -> 640 | M25: =L25*0.5 -> 320 | N25: =K25*L25 -> 11452.16 | O25: =K25*M25 -> 5726.08 | P25: 8 | Q25: 0 | R25: 0 | S25: =SUM(P25:R25) -> 8 | T25: =IF(P25=0,"0",E25/P25) -> 24.525 | U25: =IF(P25=0,"0",F25/P25) -> 12.2625 | V25: =IF(P25=0,"0",G25/P25) -> 9.196875 | W25: =IF(T25="0","0",N25/T25) -> 466.95861 | X25: =IF(U25="0","0",O25/U25) -> 466.95861 | Y25: =IF(V25="0","0",O25/V25) -> 622.61148 | Z25: =IF(Q25=0,"0",E25/Q25) -> 0 | AA25: =IF(Q25=0,"0",F25/Q25) -> 0 | AB25: =IF(Q25=0,"0",G25/Q25) -> 0 | AC25: =IF(Z25="0","0",O25/Z25) -> 0 | AD25: =IF(AA25="0","0",N25/AA25) -> 0 | AE25: =IF(AB25="0","0",O25/AB25) -> 0 | AF25: =IF(R25=0,"0",E25/R25) -> 0 | AG25: =IF(R25=0,"0",F25/R25) -> 0 | AH25: =IF(R25=0,"0",G25/R25) -> 0 | AI25: =IF(AF25="0","0",O25/AF25) -> 0 | AJ25: =IF(AG25="0","0",O25/AG25) -> 0 | AK25: =IF(AH25="0","0",N25/AH25) -> 0 | AL25: =T25+Z25+AF25 -> 24.525 | AM25: =U25+AA25+AG25 -> 12.2625 | AN25: =V25+AB25+AH25 -> 9.196875 | AO25: =IF(I25="Strap","Tensile",IF(P25>0,"Tensile","Shear")) -> Tensile | AP25: =IF(I25="Strap","Tensile",IF(Q25>0,"Tensile","Shear")) -> Shear | AQ25: =IF(I25="Strap","Tensile",IF(R25>0,"Tensile","Shear")) -> Shear | AR25: =W25+AC25+AI25 -> 466.95861 | AS25: =X25+AD25+AJ25 -> 466.95861 | AT25: =Y25+AE25+AK25 -> 622.61148
B26: 17 | C26: Refuelling Remote Panel fastened to the Utility rack at Outdoor Facilities Area | D26: 20 | E26: =D26*$D$3*$D$4 -> 784.8 | F26: =D26*$D$3*$D$5 -> 392.4 | G26: =D26*$D$3*$D$6 -> 294.3 | I26: 8.8 | J26: M6 | K26: =VLOOKUP(J26,'Fastener Data'!$E$3:$G$29,2,FALSE) -> 17.894 | L26: =VLOOKUP(I26,'Fastener Data'!$B$3:$C$18,2,FALSE) -> 640 | M26: =L26*0.5 -> 320 | N26: =K26*L26 -> 11452.16 | O26: =K26*M26 -> 5726.08 | P26: 0 | Q26: 0 | R26: 4 | S26: =SUM(P26:R26) -> 4 | T26: =IF(P26=0,"0",E26/P26) -> 0 | U26: =IF(P26=0,"0",F26/P26) -> 0 | V26: =IF(P26=0,"0",G26/P26) -> 0 | W26: =IF(T26="0","0",N26/T26) -> 0 | X26: =IF(U26="0","0",O26/U26) -> 0 | Y26: =IF(V26="0","0",O26/V26) -> 0 | Z26: =IF(Q26=0,"0",E26/Q26) -> 0 | AA26: =IF(Q26=0,"0",F26/Q26) -> 0 | AB26: =IF(Q26=0,"0",G26/Q26) -> 0 | AC26: =IF(Z26="0","0",O26/Z26) -> 0 | AD26: =IF(AA26="0","0",N26/AA26) -> 0 | AE26: =IF(AB26="0","0",O26/AB26) -> 0 | AF26: =IF(R26=0,"0",E26/R26) -> 196.2 | AG26: =IF(R26=0,"0",F26/R26) -> 98.1 | AH26: =IF(R26=0,"0",G26/R26) -> 73.575 | AI26: =IF(AF26="0","0",O26/AF26) -> 29.184913 | AJ26: =IF(AG26="0","0",O26/AG26) -> 58.369827 | AK26: =IF(AH26="0","0",N26/AH26) -> 155.65287 | AL26: =T26+Z26+AF26 -> 196.2 | AM26: =U26+AA26+AG26 -> 98.1 | AN26: =V26+AB26+AH26 -> 73.575 | AO26: =IF(I26="Strap","Tensile",IF(P26>0,"Tensile","Shear")) -> Shear | AP26: =IF(I26="Strap","Tensile",IF(Q26>0,"Tensile","Shear")) -> Shear | AQ26: =IF(I26="Strap","Tensile",IF(R26>0,"Tensile","Shear")) -> Tensile | AR26: =W26+AC26+AI26 -> 29.184913 | AS26: =X26+AD26+AJ26 -> 58.369827 | AT26: =Y26+AE26+AK26 -> 155.65287
B27: 18 | C27: Manual Pump fastened to the Utility rack at Outdoor Facilities Area | D27: 5 | E27: =D27*$D$3*$D$4 -> 196.2 | F27: =D27*$D$3*$D$5 -> 98.1 | G27: =D27*$D$3*$D$6 -> 73.575 | I27: 8.8 | J27: M6 | K27: =VLOOKUP(J27,'Fastener Data'!$E$3:$G$29,2,FALSE) -> 17.894 | L27: =VLOOKUP(I27,'Fastener Data'!$B$3:$C$18,2,FALSE) -> 640 | M27: =L27*0.5 -> 320 | N27: =K27*L27 -> 11452.16 | O27: =K27*M27 -> 5726.08 | P27: 0 | Q27: 0 | R27: 3 | S27: =SUM(P27:R27) -> 3 | T27: =IF(P27=0,"0",E27/P27) -> 0 | U27: =IF(P27=0,"0",F27/P27) -> 0 | V27: =IF(P27=0,"0",G27/P27) -> 0 | W27: =IF(T27="0","0",N27/T27) -> 0 | X27: =IF(U27="0","0",O27/U27) -> 0 | Y27: =IF(V27="0","0",O27/V27) -> 0 | Z27: =IF(Q27=0,"0",E27/Q27) -> 0 | AA27: =IF(Q27=0,"0",F27/Q27) -> 0 | AB27: =IF(Q27=0,"0",G27/Q27) -> 0 | AC27: =IF(Z27="0","0",O27/Z27) -> 0 | AD27: =IF(AA27="0","0",N27/AA27) -> 0 | AE27: =IF(AB27="0","0",O27/AB27) -> 0 | AF27: =IF(R27=0,"0",E27/R27) -> 65.4 | AG27: =IF(R27=0,"0",F27/R27) -> 32.7 | AH27: =IF(R27=0,"0",G27/R27) -> 24.525 | AI27: =IF(AF27="0","0",O27/AF27) -> 87.55474 | AJ27: =IF(AG27="0","0",O27/AG27) -> 175.10948 | AK27: =IF(AH27="0","0",N27/AH27) -> 466.95861 | AL27: =T27+Z27+AF27 -> 65.4 | AM27: =U27+AA27+AG27 -> 32.7 | AN27: =V27+AB27+AH27 -> 24.525 | AO27: =IF(I27="Strap","Tensile",IF(P27>0,"Tensile","Shear")) -> Shear | AP27: =IF(I27="Strap","Tensile",IF(Q27>0,"Tensile","Shear")) -> Shear | AQ27: =IF(I27="Strap","Tensile",IF(R27>0,"Tensile","Shear")) -> Tensile | AR27: =W27+AC27+AI27 -> 87.55474 | AS27: =X27+AD27+AJ27 -> 175.10948 | AT27: =Y27+AE27+AK27 -> 466.95861
B28: 19 | C28: 15m Pneumatic Mast (Left, Right) fastened to the base structure at LOS Mast Compartment | D28: 150 | E28: =D28*$D$3*$D$4 -> 5886 | F28: =D28*$D$3*$D$5 -> 2943 | G28: =D28*$D$3*$D$6 -> 2207.25 | I28: 8.8 | J28: M10 | K28: =VLOOKUP(J28,'Fastener Data'!$E$3:$G$29,2,FALSE) -> 52.292 | L28: =VLOOKUP(I28,'Fastener Data'!$B$3:$C$18,2,FALSE) -> 640 | M28: =L28*0.5 -> 320 | N28: =K28*L28 -> 33466.88 | O28: =K28*M28 -> 16733.44 | P28: 0 | Q28: 4 | R28: 0 | S28: =SUM(P28:R28) -> 4 | T28: =IF(P28=0,"0",E28/P28) -> 0 | U28: =IF(P28=0,"0",F28/P28) -> 0 | V28: =IF(P28=0,"0",G28/P28) -> 0 | W28: =IF(T28="0","0",N28/T28) -> 0 | X28: =IF(U28="0","0",O28/U28) -> 0 | Y28: =IF(V28="0","0",O28/V28) -> 0 | Z28: =IF(Q28=0,"0",E28/Q28) -> 1471.5 | AA28: =IF(Q28=0,"0",F28/Q28) -> 735.75 | AB28: =IF(Q28=0,"0",G28/Q28) -> 551.8125 | AC28: =IF(Z28="0","0",O28/Z28) -> 11.371689 | AD28: =IF(AA28="0","0",N28/AA28) -> 45.486755 | AE28: =IF(AB28="0","0",O28/AB28) -> 30.324503 | AF28: =IF(R28=0,"0",E28/R28) -> 0 | AG28: =IF(R28=0,"0",F28/R28) -> 0 | AH28: =IF(R28=0,"0",G28/R28) -> 0 | AI28: =IF(AF28="0","0",O28/AF28) -> 0 | AJ28: =IF(AG28="0","0",O28/AG28) -> 0 | AK28: =IF(AH28="0","0",N28/AH28) -> 0 | AL28: =T28+Z28+AF28 -> 1471.5 | AM28: =U28+AA28+AG28 -> 735.75 | AN28: =V28+AB28+AH28 -> 551.8125 | AO28: =IF(I28="Strap","Tensile",IF(P28>0,"Tensile","Shear")) -> Shear | AP28: =IF(I28="Strap","Tensile",IF(Q28>0,"Tensile","Shear")) -> Tensile | AQ28: =IF(I28="Strap","Tensile",IF(R28>0,"Tensile","Shear")) -> Shear | AR28: =W28+AC28+AI28 -> 11.371689 | AS28: =X28+AD28+AJ28 -> 45.486755 | AT28: =Y28+AE28+AK28 -> 30.324503
B29: 20 | C29: Mast Compressor (left, Right) fastened to the base structure at LOS Mast Compartment | D29: 22 | E29: =D29*$D$3*$D$4 -> 863.28 | F29: =D29*$D$3*$D$5 -> 431.64 | G29: =D29*$D$3*$D$6 -> 323.73 | I29: 8.8 | J29: M6 | K29: =VLOOKUP(J29,'Fastener Data'!$E$3:$G$29,2,FALSE) -> 17.894 | L29: =VLOOKUP(I29,'Fastener Data'!$B$3:$C$18,2,FALSE) -> 640 | M29: =L29*0.5 -> 320 | N29: =K29*L29 -> 11452.16 | O29: =K29*M29 -> 5726.08 | P29: 0 | Q29: 4 | R29: 0 | S29: =SUM(P29:R29) -> 4 | T29: =IF(P29=0,"0",E29/P29) -> 0 | U29: =IF(P29=0,"0",F29/P29) -> 0 | V29: =IF(P29=0,"0",G29/P29) -> 0 | W29: =IF(T29="0","0",N29/T29) -> 0 | X29: =IF(U29="0","0",O29/U29) -> 0 | Y29: =IF(V29="0","0",O29/V29) -> 0 | Z29: =IF(Q29=0,"0",E29/Q29) -> 215.82 | AA29: =IF(Q29=0,"0",F29/Q29) -> 107.91 | AB29: =IF(Q29=0,"0",G29/Q29) -> 80.9325 | AC29: =IF(Z29="0","0",O29/Z29) -> 26.531739 | AD29: =IF(AA29="0","0",N29/AA29) -> 106.12696 | AE29: =IF(AB29="0","0",O29/AB29) -> 70.751305 | AF29: =IF(R29=0,"0",E29/R29) -> 0 | AG29: =IF(R29=0,"0",F29/R29) -> 0 | AH29: =IF(R29=0,"0",G29/R29) -> 0 | AI29: =IF(AF29="0","0",O29/AF29) -> 0 | AJ29: =IF(AG29="0","0",O29/AG29) -> 0 | AK29: =IF(AH29="0","0",N29/AH29) -> 0 | AL29: =T29+Z29+AF29 -> 215.82 | AM29: =U29+AA29+AG29 -> 107.91 | AN29: =V29+AB29+AH29 -> 80.9325 | AO29: =IF(I29="Strap","Tensile",IF(P29>0,"Tensile","Shear")) -> Shear | AP29: =IF(I29="Strap","Tensile",IF(Q29>0,"Tensile","Shear")) -> Tensile | AQ29: =IF(I29="Strap","Tensile",IF(R29>0,"Tensile","Shear")) -> Shear | AR29: =W29+AC29+AI29 -> 26.531739 | AS29: =X29+AD29+AJ29 -> 106.12696 | AT29: =Y29+AE29+AK29 -> 70.751305
B30: 21 | C30: EM Mast w/fixed payload (LTE Antennas & Mounting) fastened to the base structure at EM mast compartment | D30: 251 | E30: =D30*$D$3*$D$4 -> 9849.24 | F30: =D30*$D$3*$D$5 -> 4924.62 | G30: =D30*$D$3*$D$6 -> 3693.465 | I30: 8.8 | J30: M12 | K30: =VLOOKUP(J30,'Fastener Data'!$E$3:$G$29,2,FALSE) -> 76.247 | L30: =VLOOKUP(I30,'Fastener Data'!$B$3:$C$18,2,FALSE) -> 640 | M30: =L30*0.5 -> 320 | N30: =K30*L30 -> 48798.08 | O30: =K30*M30 -> 24399.04 | P30: 0 | Q30: 4 | R30: 0 | S30: =SUM(P30:R30) -> 4 | T30: =IF(P30=0,"0",E30/P30) -> 0 | U30: =IF(P30=0,"0",F30/P30) -> 0 | V30: =IF(P30=0,"0",G30/P30) -> 0 | W30: =IF(T30="0","0",N30/T30) -> 0 | X30: =IF(U30="0","0",O30/U30) -> 0 | Y30: =IF(V30="0","0",O30/V30) -> 0 | Z30: =IF(Q30=0,"0",E30/Q30) -> 2462.31 | AA30: =IF(Q30=0,"0",F30/Q30) -> 1231.155 | AB30: =IF(Q30=0,"0",G30/Q30) -> 923.36625 | AC30: =IF(Z30="0","0",O30/Z30) -> 9.9090041 | AD30: =IF(AA30="0","0",N30/AA30) -> 39.636017 | AE30: =IF(AB30="0","0",O30/AB30) -> 26.424011 | AF30: =IF(R30=0,"0",E30/R30) -> 0 | AG30: =IF(R30=0,"0",F30/R30) -> 0 | AH30: =IF(R30=0,"0",G30/R30) -> 0 | AI30: =IF(AF30="0","0",O30/AF30) -> 0 | AJ30: =IF(AG30="0","0",O30/AG30) -> 0 | AK30: =IF(AH30="0","0",N30/AH30) -> 0 | AL30: =T30+Z30+AF30 -> 2462.31 | AM30: =U30+AA30+AG30 -> 1231.155 | AN30: =V30+AB30+AH30 -> 923.36625 | AO30: =IF(I30="Strap","Tensile",IF(P30>0,"Tensile","Shear")) -> Shear | AP30: =IF(I30="Strap","Tensile",IF(Q30>0,"Tensile","Shear")) -> Tensile | AQ30: =IF(I30="Strap","Tensile",IF(R30>0,"Tensile","Shear")) -> Shear | AR30: =W30+AC30+AI30 -> 9.9090041 | AS30: =X30+AD30+AJ30 -> 39.636017 | AT30: =Y30+AE30+AK30 -> 26.424011
B31: 22 | C31: EM Mast Main Controller fastened to front wall | D31: 5 | E31: =D31*$D$3*$D$4 -> 196.2 | F31: =D31*$D$3*$D$5 -> 98.1 | G31: =D31*$D$3*$D$6 -> 73.575 | I31: 8.8 | J31: M6 | K31: =VLOOKUP(J31,'Fastener Data'!$E$3:$G$29,2,FALSE) -> 17.894 | L31: =VLOOKUP(I31,'Fastener Data'!$B$3:$C$18,2,FALSE) -> 640 | M31: =0.5*L31 -> 320 | N31: =K31*L31 -> 11452.16 | O31: =K31*M31 -> 5726.08 | P31: 6 | Q31: 0 | R31: 0 | S31: =SUM(P31:R31) -> 6 | T31: =IF(P31=0,"0",E31/P31) -> 32.7 | U31: =IF(P31=0,"0",F31/P31) -> 16.35 | V31: =IF(P31=0,"0",G31/P31) -> 12.2625 | W31: =IF(T31="0","0",N31/T31) -> 350.21896 | X31: =IF(U31="0","0",O31/U31) -> 350.21896 | Y31: =IF(V31="0","0",O31/V31) -> 466.95861 | Z31: =IF(Q31=0,"0",E31/Q31) -> 0 | AA31: =IF(Q31=0,"0",F31/Q31) -> 0 | AB31: =IF(Q31=0,"0",G31/Q31) -> 0 | AC31: =IF(Z31="0","0",O31/Z31) -> 0 | AD31: =IF(AA31="0","0",N31/AA31) -> 0 | AE31: =IF(AB31="0","0",O31/AB31) -> 0 | AF31: =IF(R31=0,"0",E31/R31) -> 0 | AG31: =IF(R31=0,"0",F31/R31) -> 0 | AH31: =IF(R31=0,"0",G31/R31) -> 0 | AI31: =IF(AF31="0","0",O31/AF31) -> 0 | AJ31: =IF(AG31="0","0",O31/AG31) -> 0 | AK31: =IF(AH31="0","0",N31/AH31) -> 0 | AL31: =T31+Z31+AF31 -> 32.7 | AM31: =U31+AA31+AG31 -> 16.35 | AN31: =V31+AB31+AH31 -> 12.2625 | AO31: =IF(I31="Strap","Tensile",IF(P31>0,"Tensile","Shear")) -> Tensile | AP31: =IF(I31="Strap","Tensile",IF(Q31>0,"Tensile","Shear")) -> Shear | AQ31: =IF(I31="Strap","Tensile",IF(R31>0,"Tensile","Shear")) -> Shear | AR31: =W31+AC31+AI31 -> 350.21896 | AS31: =X31+AD31+AJ31 -> 350.21896 | AT31: =Y31+AE31+AK31 -> 466.95861
B32: 23 | C32: EM Mast Handheld Remote Control fastened to front wall | D32: 3 | E32: =D32*$D$3*$D$4 -> 117.72 | F32: =D32*$D$3*$D$5 -> 58.86 | G32: =D32*$D$3*$D$6 -> 44.145 | I32: 8.8 | J32: M6 | K32: =VLOOKUP(J32,'Fastener Data'!$E$3:$G$29,2,FALSE) -> 17.894 | L32: =VLOOKUP(I32,'Fastener Data'!$B$3:$C$18,2,FALSE) -> 640 | M32: =0.5*L32 -> 320 | N32: =K32*L32 -> 11452.16 | O32: =K32*M32 -> 5726.08 | P32: 4 | Q32: 0 | R32: 0 | S32: =SUM(P32:R32) -> 4 | T32: =IF(P32=0,"0",E32/P32) -> 29.43 | U32: =IF(P32=0,"0",F32/P32) -> 14.715 | V32: =IF(P32=0,"0",G32/P32) -> 11.03625 | W32: =IF(T32="0","0",N32/T32) -> 389.13218 | X32: =IF(U32="0","0",O32/U32) -> 389.13218 | Y32: =IF(V32="0","0",O32/V32) -> 518.8429 | Z32: =IF(Q32=0,"0",E32/Q32) -> 0 | AA32: =IF(Q32=0,"0",F32/Q32) -> 0 | AB32: =IF(Q32=0,"0",G32/Q32) -> 0 | AC32: =IF(Z32="0","0",O32/Z32) -> 0 | AD32: =IF(AA32="0","0",N32/AA32) -> 0 | AE32: =IF(AB32="0","0",O32/AB32) -> 0 | AF32: =IF(R32=0,"0",E32/R32) -> 0 | AG32: =IF(R32=0,"0",F32/R32) -> 0 | AH32: =IF(R32=0,"0",G32/R32) -> 0 | AI32: =IF(AF32="0","0",O32/AF32) -> 0 | AJ32: =IF(AG32="0","0",O32/AG32) -> 0 | AK32: =IF(AH32="0","0",N32/AH32) -> 0 | AL32: =T32+Z32+AF32 -> 29.43 | AM32: =U32+AA32+AG32 -> 14.715 | AN32: =V32+AB32+AH32 -> 11.03625 | AO32: =IF(I32="Strap","Tensile",IF(P32>0,"Tensile","Shear")) -> Tensile | AP32: =IF(I32="Strap","Tensile",IF(Q32>0,"Tensile","Shear")) -> Shear | AQ32: =IF(I32="Strap","Tensile",IF(R32>0,"Tensile","Shear")) -> Shear | AR32: =W32+AC32+AI32 -> 389.13218 | AS32: =X32+AD32+AJ32 -> 389.13218 | AT32: =Y32+AE32+AK32 -> 518.8429
B33: 24 | C33: EM Mast Capacity Bank fastened to front wall | D33: 10.8 | E33: =D33*$D$3*$D$4 -> 423.792 | F33: =D33*$D$3*$D$5 -> 211.896 | G33: =D33*$D$3*$D$6 -> 158.922 | I33: 8.8 | J33: M6 | K33: =VLOOKUP(J33,'Fastener Data'!$E$3:$G$29,2,FALSE) -> 17.894 | L33: =VLOOKUP(I33,'Fastener Data'!$B$3:$C$18,2,FALSE) -> 640 | M33: =0.5*L33 -> 320 | N33: =K33*L33 -> 11452.16 | O33: =K33*M33 -> 5726.08 | P33: 4 | Q33: 0 | R33: 0 | S33: =SUM(P33:R33) -> 4 | T33: =IF(P33=0,"0",E33/P33) -> 105.948 | U33: =IF(P33=0,"0",F33/P33) -> 52.974 | V33: =IF(P33=0,"0",G33/P33) -> 39.7305 | W33: =IF(T33="0","0",N33/T33) -> 108.09227 | X33: =IF(U33="0","0",O33/U33) -> 108.09227 | Y33: =IF(V33="0","0",O33/V33) -> 144.12303 | Z33: =IF(Q33=0,"0",E33/Q33) -> 0 | AA33: =IF(Q33=0,"0",F33/Q33) -> 0 | AB33: =IF(Q33=0,"0",G33/Q33) -> 0 | AC33: =IF(Z33="0","0",O33/Z33) -> 0 | AD33: =IF(AA33="0","0",N33/AA33) -> 0 | AE33: =IF(AB33="0","0",O33/AB33) -> 0 | AF33: =IF(R33=0,"0",E33/R33) -> 0 | AG33: =IF(R33=0,"0",F33/R33) -> 0 | AH33: =IF(R33=0,"0",G33/R33) -> 0 | AI33: =IF(AF33="0","0",O33/AF33) -> 0 | AJ33: =IF(AG33="0","0",O33/AG33) -> 0 | AK33: =IF(AH33="0","0",N33/AH33) -> 0 | AL33: =T33+Z33+AF33 -> 105.948 | AM33: =U33+AA33+AG33 -> 52.974 | AN33: =V33+AB33+AH33 -> 39.7305 | AO33: =IF(I33="Strap","Tensile",IF(P33>0,"Tensile","Shear")) -> Tensile | AP33: =IF(I33="Strap","Tensile",IF(Q33>0,"Tensile","Shear")) -> Shear | AQ33: =IF(I33="Strap","Tensile",IF(R33>0,"Tensile","Shear")) -> Shear | AR33: =W33+AC33+AI33 -> 108.09227 | AS33: =X33+AD33+AJ33 -> 108.09227 | AT33: =Y33+AE33+AK33 -> 144.12303
B34: 25 | C34: Front Protective Guard fastened to the top beam at Outdoor Facilities Area | D34: 6 | E34: =D34*$D$3*$D$4 -> 235.44 | F34: =D34*$D$3*$D$5 -> 117.72 | G34: =D34*$D$3*$D$6 -> 88.29 | I34: 8.8 | J34: M6 | K34: =VLOOKUP(J34,'Fastener Data'!$E$3:$G$29,2,FALSE) -> 17.894 | L34: =VLOOKUP(I34,'Fastener Data'!$B$3:$C$18,2,FALSE) -> 640 | M34: =L34*0.5 -> 320 | N34: =K34*L34 -> 11452.16 | O34: =K34*M34 -> 5726.08 | P34: 12 | Q34: 0 | R34: 0 | S34: =SUM(P34:R34) -> 12 | T34: =IF(P34=0,"0",E34/P34) -> 19.62 | U34: =IF(P34=0,"0",F34/P34) -> 9.81 | V34: =IF(P34=0,"0",G34/P34) -> 7.3575 | W34: =IF(T34="0","0",N34/T34) -> 583.69827 | X34: =IF(U34="0","0",O34/U34) -> 583.69827 | Y34: =IF(V34="0","0",O34/V34) -> 778.26436 | Z34: =IF(Q34=0,"0",E34/Q34) -> 0 | AA34: =IF(Q34=0,"0",F34/Q34) -> 0 | AB34: =IF(Q34=0,"0",G34/Q34) -> 0 | AC34: =IF(Z34="0","0",O34/Z34) -> 0 | AD34: =IF(AA34="0","0",N34/AA34) -> 0 | AE34: =IF(AB34="0","0",O34/AB34) -> 0 | AF34: =IF(R34=0,"0",E34/R34) -> 0 | AG34: =IF(R34=0,"0",F34/R34) -> 0 | AH34: =IF(R34=0,"0",G34/R34) -> 0 | AI34: =IF(AF34="0","0",O34/AF34) -> 0 | AJ34: =IF(AG34="0","0",O34/AG34) -> 0 | AK34: =IF(AH34="0","0",N34/AH34) -> 0 | AL34: =T34+Z34+AF34 -> 19.62 | AM34: =U34+AA34+AG34 -> 9.81 | AN34: =V34+AB34+AH34 -> 7.3575 | AO34: =IF(I34="Strap","Tensile",IF(P34>0,"Tensile","Shear")) -> Tensile | AP34: =IF(I34="Strap","Tensile",IF(Q34>0,"Tensile","Shear")) -> Shear | AQ34: =IF(I34="Strap","Tensile",IF(R34>0,"Tensile","Shear")) -> Shear | AR34: =W34+AC34+AI34 -> 583.69827 | AS34: =X34+AD34+AJ34 -> 583.69827 | AT34: =Y34+AE34+AK34 -> 778.26436
B35: 26 | C35: Left Protective Guard fastened to the top beam at Outdoor Facilities Area | D35: 6 | E35: =D35*$D$3*$D$4 -> 235.44 | F35: =D35*$D$3*$D$5 -> 117.72 | G35: =D35*$D$3*$D$6 -> 88.29 | I35: 8.8 | J35: M8 | K35: =VLOOKUP(J35,'Fastener Data'!$E$3:$G$29,2,FALSE) -> 32.841 | L35: =VLOOKUP(I35,'Fastener Data'!$B$3:$C$18,2,FALSE) -> 640 | M35: =0.5*L35 -> 320 | N35: =K35*L35 -> 21018.24 | O35: =K35*M35 -> 10509.12 | P35: 0 | Q35: 0 | R35: 12 | S35: =SUM(P35:R35) -> 12 | T35: =IF(P35=0,"0",E35/P35) -> 0 | U35: =IF(P35=0,"0",F35/P35) -> 0 | V35: =IF(P35=0,"0",G35/P35) -> 0 | W35: =IF(T35="0","0",N35/T35) -> 0 | X35: =IF(U35="0","0",O35/U35) -> 0 | Y35: =IF(V35="0","0",O35/V35) -> 0 | Z35: =IF(Q35=0,"0",E35/Q35) -> 0 | AA35: =IF(Q35=0,"0",F35/Q35) -> 0 | AB35: =IF(Q35=0,"0",G35/Q35) -> 0 | AC35: =IF(Z35="0","0",O35/Z35) -> 0 | AD35: =IF(AA35="0","0",N35/AA35) -> 0 | AE35: =IF(AB35="0","0",O35/AB35) -> 0 | AF35: =IF(R35=0,"0",E35/R35) -> 19.62 | AG35: =IF(R35=0,"0",F35/R35) -> 9.81 | AH35: =IF(R35=0,"0",G35/R35) -> 7.3575 | AI35: =IF(AF35="0","0",O35/AF35) -> 535.63303 | AJ35: =IF(AG35="0","0",O35/AG35) -> 1071.2661 | AK35: =IF(AH35="0","0",N35/AH35) -> 2856.7095 | AL35: =T35+Z35+AF35 -> 19.62 | AM35: =U35+AA35+AG35 -> 9.81 | AN35: =V35+AB35+AH35 -> 7.3575 | AO35: =IF(I35="Strap","Tensile",IF(P35>0,"Tensile","Shear")) -> Shear | AP35: =IF(I35="Strap","Tensile",IF(Q35>0,"Tensile","Shear")) -> Shear | AQ35: =IF(I35="Strap","Tensile",IF(R35>0,"Tensile","Shear")) -> Tensile | AR35: =W35+AC35+AI35 -> 535.63303 | AS35: =X35+AD35+AJ35 -> 1071.2661 | AT35: =Y35+AE35+AK35 -> 2856.7095
B36: 27 | C36: Right Protective Guard fastened to the top beam at Outdoor Facilities Area | D36: 4 | E36: =D36*$D$3*$D$4 -> 156.96 | F36: =D36*$D$3*$D$5 -> 78.48 | G36: =D36*$D$3*$D$6 -> 58.86 | I36: 8.8 | J36: M8 | K36: =VLOOKUP(J36,'Fastener Data'!$E$3:$G$29,2,FALSE) -> 32.841 | L36: =VLOOKUP(I36,'Fastener Data'!$B$3:$C$18,2,FALSE) -> 640 | M36: =0.5*L36 -> 320 | N36: =K36*L36 -> 21018.24 | O36: =K36*M36 -> 10509.12 | P36: 0 | Q36: 0 | R36: 8 | S36: =SUM(P36:R36) -> 8 | T36: =IF(P36=0,"0",E36/P36) -> 0 | U36: =IF(P36=0,"0",F36/P36) -> 0 | V36: =IF(P36=0,"0",G36/P36) -> 0 | W36: =IF(T36="0","0",N36/T36) -> 0 | X36: =IF(U36="0","0",O36/U36) -> 0 | Y36: =IF(V36="0","0",O36/V36) -> 0 | Z36: =IF(Q36=0,"0",E36/Q36) -> 0 | AA36: =IF(Q36=0,"0",F36/Q36) -> 0 | AB36: =IF(Q36=0,"0",G36/Q36) -> 0 | AC36: =IF(Z36="0","0",O36/Z36) -> 0 | AD36: =IF(AA36="0","0",N36/AA36) -> 0 | AE36: =IF(AB36="0","0",O36/AB36) -> 0 | AF36: =IF(R36=0,"0",E36/R36) -> 19.62 | AG36: =IF(R36=0,"0",F36/R36) -> 9.81 | AH36: =IF(R36=0,"0",G36/R36) -> 7.3575 | AI36: =IF(AF36="0","0",O36/AF36) -> 535.63303 | AJ36: =IF(AG36="0","0",O36/AG36) -> 1071.2661 | AK36: =IF(AH36="0","0",N36/AH36) -> 2856.7095 | AL36: =T36+Z36+AF36 -> 19.62 | AM36: =U36+AA36+AG36 -> 9.81 | AN36: =V36+AB36+AH36 -> 7.3575 | AO36: =IF(I36="Strap","Tensile",IF(P36>0,"Tensile","Shear")) -> Shear | AP36: =IF(I36="Strap","Tensile",IF(Q36>0,"Tensile","Shear")) -> Shear | AQ36: =IF(I36="Strap","Tensile",IF(R36>0,"Tensile","Shear")) -> Tensile | AR36: =W36+AC36+AI36 -> 535.63303 | AS36: =X36+AD36+AJ36 -> 1071.2661 | AT36: =Y36+AE36+AK36 -> 2856.7095
B37: 28 | C37: Lower Guard Front (1, 2) fastened to the front beams at Outdoor Facilities Area | D37: 3 | E37: =D37*$D$3*$D$4 -> 117.72 | F37: =D37*$D$3*$D$5 -> 58.86 | G37: =D37*$D$3*$D$6 -> 44.145 | I37: 8.8 | J37: M6 | K37: =VLOOKUP(J37,'Fastener Data'!$E$3:$G$29,2,FALSE) -> 17.894 | L37: =VLOOKUP(I37,'Fastener Data'!$B$3:$C$18,2,FALSE) -> 640 | M37: =L37*0.5 -> 320 | N37: =K37*L37 -> 11452.16 | O37: =K37*M37 -> 5726.08 | P37: 6 | Q37: 0 | R37: 0 | S37: =SUM(P37:R37) -> 6 | T37: =IF(P37=0,"0",E37/P37) -> 19.62 | U37: =IF(P37=0,"0",F37/P37) -> 9.81 | V37: =IF(P37=0,"0",G37/P37) -> 7.3575 | W37: =IF(T37="0","0",N37/T37) -> 583.69827 | X37: =IF(U37="0","0",O37/U37) -> 583.69827 | Y37: =IF(V37="0","0",O37/V37) -> 778.26436 | Z37: =IF(Q37=0,"0",E37/Q37) -> 0 | AA37: =IF(Q37=0,"0",F37/Q37) -> 0 | AB37: =IF(Q37=0,"0",G37/Q37) -> 0 | AC37: =IF(Z37="0","0",O37/Z37) -> 0 | AD37: =IF(AA37="0","0",N37/AA37) -> 0 | AE37: =IF(AB37="0","0",O37/AB37) -> 0 | AF37: =IF(R37=0,"0",E37/R37) -> 0 | AG37: =IF(R37=0,"0",F37/R37) -> 0 | AH37: =IF(R37=0,"0",G37/R37) -> 0 | AI37: =IF(AF37="0","0",O37/AF37) -> 0 | AJ37: =IF(AG37="0","0",O37/AG37) -> 0 | AK37: =IF(AH37="0","0",N37/AH37) -> 0 | AL37: =T37+Z37+AF37 -> 19.62 | AM37: =U37+AA37+AG37 -> 9.81 | AN37: =V37+AB37+AH37 -> 7.3575 | AO37: =IF(I37="Strap","Tensile",IF(P37>0,"Tensile","Shear")) -> Tensile | AP37: =IF(I37="Strap","Tensile",IF(Q37>0,"Tensile","Shear")) -> Shear | AQ37: =IF(I37="Strap","Tensile",IF(R37>0,"Tensile","Shear")) -> Shear | AR37: =W37+AC37+AI37 -> 583.69827 | AS37: =X37+AD37+AJ37 -> 583.69827 | AT37: =Y37+AE37+AK37 -> 778.26436
B38: 29 | C38: Lower Guard Left (1, 2) & Lower Guard Right fastened to the side beams at Outdoor Facilities Area | D38: 3 | E38: =D38*$D$3*$D$4 -> 117.72 | F38: =D38*$D$3*$D$5 -> 58.86 | G38: =D38*$D$3*$D$6 -> 44.145 | I38: 8.8 | J38: M6 | K38: =VLOOKUP(J38,'Fastener Data'!$E$3:$G$29,2,FALSE) -> 17.894 | L38: =VLOOKUP(I38,'Fastener Data'!$B$3:$C$18,2,FALSE) -> 640 | M38: =0.5*L38 -> 320 | N38: =K38*L38 -> 11452.16 | O38: =K38*M38 -> 5726.08 | P38: 0 | Q38: 8 | R38: 0 | S38: =SUM(P38:R38) -> 8 | T38: =IF(P38=0,"0",E38/P38) -> 0 | U38: =IF(P38=0,"0",F38/P38) -> 0 | V38: =IF(P38=0,"0",G38/P38) -> 0 | W38: =IF(T38="0","0",N38/T38) -> 0 | X38: =IF(U38="0","0",O38/U38) -> 0 | Y38: =IF(V38="0","0",O38/V38) -> 0 | Z38: =IF(Q38=0,"0",E38/Q38) -> 14.715 | AA38: =IF(Q38=0,"0",F38/Q38) -> 7.3575 | AB38: =IF(Q38=0,"0",G38/Q38) -> 5.518125 | AC38: =IF(Z38="0","0",O38/Z38) -> 389.13218 | AD38: =IF(AA38="0","0",N38/AA38) -> 1556.5287 | AE38: =IF(AB38="0","0",O38/AB38) -> 1037.6858 | AF38: =IF(R38=0,"0",E38/R38) -> 0 | AG38: =IF(R38=0,"0",F38/R38) -> 0 | AH38: =IF(R38=0,"0",G38/R38) -> 0 | AI38: =IF(AF38="0","0",O38/AF38) -> 0 | AJ38: =IF(AG38="0","0",O38/AG38) -> 0 | AK38: =IF(AH38="0","0",N38/AH38) -> 0 | AL38: =T38+Z38+AF38 -> 14.715 | AM38: =U38+AA38+AG38 -> 7.3575 | AN38: =V38+AB38+AH38 -> 5.518125 | AO38: =IF(I38="Strap","Tensile",IF(P38>0,"Tensile","Shear")) -> Shear | AP38: =IF(I38="Strap","Tensile",IF(Q38>0,"Tensile","Shear")) -> Tensile | AQ38: =IF(I38="Strap","Tensile",IF(R38>0,"Tensile","Shear")) -> Shear | AR38: =W38+AC38+AI38 -> 389.13218 | AS38: =X38+AD38+AJ38 -> 1556.5287 | AT38: =Y38+AE38+AK38 -> 1037.6858
B39: 30 | C39: ODU Guard (1, 2) fastened to the left side beams at Outdoor Facilities Area | D39: 4 | E39: =D39*$D$3*$D$4 -> 156.96 | F39: =D39*$D$3*$D$5 -> 78.48 | G39: =D39*$D$3*$D$6 -> 58.86 | I39: 8.8 | J39: M6 | K39: =VLOOKUP(J39,'Fastener Data'!$E$3:$G$29,2,FALSE) -> 17.894 | L39: =VLOOKUP(I39,'Fastener Data'!$B$3:$C$18,2,FALSE) -> 640 | M39: =0.5*L39 -> 320 | N39: =K39*L39 -> 11452.16 | O39: =K39*M39 -> 5726.08 | P39: 0 | Q39: 0 | R39: 6 | S39: =SUM(P39:R39) -> 6 | T39: =IF(P39=0,"0",E39/P39) -> 0 | U39: =IF(P39=0,"0",F39/P39) -> 0 | V39: =IF(P39=0,"0",G39/P39) -> 0 | W39: =IF(T39="0","0",N39/T39) -> 0 | X39: =IF(U39="0","0",O39/U39) -> 0 | Y39: =IF(V39="0","0",O39/V39) -> 0 | Z39: =IF(Q39=0,"0",E39/Q39) -> 0 | AA39: =IF(Q39=0,"0",F39/Q39) -> 0 | AB39: =IF(Q39=0,"0",G39/Q39) -> 0 | AC39: =IF(Z39="0","0",O39/Z39) -> 0 | AD39: =IF(AA39="0","0",N39/AA39) -> 0 | AE39: =IF(AB39="0","0",O39/AB39) -> 0 | AF39: =IF(R39=0,"0",E39/R39) -> 26.16 | AG39: =IF(R39=0,"0",F39/R39) -> 13.08 | AH39: =IF(R39=0,"0",G39/R39) -> 9.81 | AI39: =IF(AF39="0","0",O39/AF39) -> 218.88685 | AJ39: =IF(AG39="0","0",O39/AG39) -> 437.7737 | AK39: =IF(AH39="0","0",N39/AH39) -> 1167.3965 | AL39: =T39+Z39+AF39 -> 26.16 | AM39: =U39+AA39+AG39 -> 13.08 | AN39: =V39+AB39+AH39 -> 9.81 | AO39: =IF(I39="Strap","Tensile",IF(P39>0,"Tensile","Shear")) -> Shear | AP39: =IF(I39="Strap","Tensile",IF(Q39>0,"Tensile","Shear")) -> Shear | AQ39: =IF(I39="Strap","Tensile",IF(R39>0,"Tensile","Shear")) -> Tensile | AR39: =W39+AC39+AI39 -> 218.88685 | AS39: =X39+AD39+AJ39 -> 437.7737 | AT39: =Y39+AE39+AK39 -> 1167.3965
B40: 31 | C40: LTE Antenna Big (1,2,3) fastened on top of the EM mast | D40: 7 | E40: =D40*$D$3*$D$4 -> 274.68 | F40: =D40*$D$3*$D$5 -> 137.34 | G40: =D40*$D$3*$D$6 -> 103.005 | I40: 8.8 | J40: M8 | K40: =VLOOKUP(J40,'Fastener Data'!$E$3:$G$29,2,FALSE) -> 32.841 | L40: =VLOOKUP(I40,'Fastener Data'!$B$3:$C$18,2,FALSE) -> 640 | M40: =L40*0.5 -> 320 | N40: =K40*L40 -> 21018.24 | O40: =K40*M40 -> 10509.12 | P40: 0 | Q40: 0 | R40: 4 | S40: =SUM(P40:R40) -> 4 | T40: =IF(P40=0,"0",E40/P40) -> 0 | U40: =IF(P40=0,"0",F40/P40) -> 0 | V40: =IF(P40=0,"0",G40/P40) -> 0 | W40: =IF(T40="0","0",N40/T40) -> 0 | X40: =IF(U40="0","0",O40/U40) -> 0 | Y40: =IF(V40="0","0",O40/V40) -> 0 | Z40: =IF(Q40=0,"0",E40/Q40) -> 0 | AA40: =IF(Q40=0,"0",F40/Q40) -> 0 | AB40: =IF(Q40=0,"0",G40/Q40) -> 0 | AC40: =IF(Z40="0","0",O40/Z40) -> 0 | AD40: =IF(AA40="0","0",N40/AA40) -> 0 | AE40: =IF(AB40="0","0",O40/AB40) -> 0 | AF40: =IF(R40=0,"0",E40/R40) -> 68.67 | AG40: =IF(R40=0,"0",F40/R40) -> 34.335 | AH40: =IF(R40=0,"0",G40/R40) -> 25.75125 | AI40: =IF(AF40="0","0",O40/AF40) -> 153.03801 | AJ40: =IF(AG40="0","0",O40/AG40) -> 306.07602 | AK40: =IF(AH40="0","0",N40/AH40) -> 816.20271 | AL40: =T40+Z40+AF40 -> 68.67 | AM40: =U40+AA40+AG40 -> 34.335 | AN40: =V40+AB40+AH40 -> 25.75125 | AO40: =IF(I40="Strap","Tensile",IF(P40>0,"Tensile","Shear")) -> Shear | AP40: =IF(I40="Strap","Tensile",IF(Q40>0,"Tensile","Shear")) -> Shear | AQ40: =IF(I40="Strap","Tensile",IF(R40>0,"Tensile","Shear")) -> Tensile | AR40: =W40+AC40+AI40 -> 153.03801 | AS40: =X40+AD40+AJ40 -> 306.07602 | AT40: =Y40+AE40+AK40 -> 816.20271
B41: 32 | C41: LTE Antenna Small (1,2,3) fastened on top of the EM mast | D41: 2.8 | E41: =D41*$D$3*$D$4 -> 109.872 | F41: =D41*$D$3*$D$5 -> 54.936 | G41: =D41*$D$3*$D$6 -> 41.202 | I41: 8.8 | J41: M8 | K41: =VLOOKUP(J41,'Fastener Data'!$E$3:$G$29,2,FALSE) -> 32.841 | L41: =VLOOKUP(I41,'Fastener Data'!$B$3:$C$18,2,FALSE) -> 640 | M41: =0.5*L41 -> 320 | N41: =K41*L41 -> 21018.24 | O41: =K41*M41 -> 10509.12 | P41: 0 | Q41: 0 | R41: 4 | S41: =SUM(P41:R41) -> 4 | T41: =IF(P41=0,"0",E41/P41) -> 0 | U41: =IF(P41=0,"0",F41/P41) -> 0 | V41: =IF(P41=0,"0",G41/P41) -> 0 | W41: =IF(T41="0","0",N41/T41) -> 0 | X41: =IF(U41="0","0",O41/U41) -> 0 | Y41: =IF(V41="0","0",O41/V41) -> 0 | Z41: =IF(Q41=0,"0",E41/Q41) -> 0 | AA41: =IF(Q41=0,"0",F41/Q41) -> 0 | AB41: =IF(Q41=0,"0",G41/Q41) -> 0 | AC41: =IF(Z41="0","0",O41/Z41) -> 0 | AD41: =IF(AA41="0","0",N41/AA41) -> 0 | AE41: =IF(AB41="0","0",O41/AB41) -> 0 | AF41: =IF(R41=0,"0",E41/R41) -> 27.468 | AG41: =IF(R41=0,"0",F41/R41) -> 13.734 | AH41: =IF(R41=0,"0",G41/R41) -> 10.3005 | AI41: =IF(AF41="0","0",O41/AF41) -> 382.59502 | AJ41: =IF(AG41="0","0",O41/AG41) -> 765.19004 | AK41: =IF(AH41="0","0",N41/AH41) -> 2040.5068 | AL41: =T41+Z41+AF41 -> 27.468 | AM41: =U41+AA41+AG41 -> 13.734 | AN41: =V41+AB41+AH41 -> 10.3005 | AO41: =IF(I41="Strap","Tensile",IF(P41>0,"Tensile","Shear")) -> Shear | AP41: =IF(I41="Strap","Tensile",IF(Q41>0,"Tensile","Shear")) -> Shear | AQ41: =IF(I41="Strap","Tensile",IF(R41>0,"Tensile","Shear")) -> Tensile | AR41: =W41+AC41+AI41 -> 382.59502 | AS41: =X41+AD41+AJ41 -> 765.19004 | AT41: =Y41+AE41+AK41 -> 2040.5068
B42: 33 | C42: LTE Antenna Mounting w/ LTE Antennas fastened on top of the EM mast | D42: 91 | E42: =D42*$D$3*$D$4 -> 3570.84 | F42: =D42*$D$3*$D$5 -> 1785.42 | G42: =D42*$D$3*$D$6 -> 1339.065 | I42: 8.8 | J42: 1/4-20 | K42: =VLOOKUP(J42,'Fastener Data'!$E$3:$G$29,2,FALSE) -> 21.711909 | L42: =VLOOKUP(I42,'Fastener Data'!$B$3:$C$18,2,FALSE) -> 640 | M42: =0.5*L42 -> 320 | N42: =K42*L42 -> 13895.622 | O42: =K42*M42 -> 6947.8108 | P42: 0 | Q42: 6 | R42: 0 | S42: =SUM(P42:R42) -> 6 | T42: =IF(P42=0,"0",E42/P42) -> 0 | U42: =IF(P42=0,"0",F42/P42) -> 0 | V42: =IF(P42=0,"0",G42/P42) -> 0 | W42: =IF(T42="0","0",N42/T42) -> 0 | X42: =IF(U42="0","0",O42/U42) -> 0 | Y42: =IF(V42="0","0",O42/V42) -> 0 | Z42: =IF(Q42=0,"0",E42/Q42) -> 595.14 | AA42: =IF(Q42=0,"0",F42/Q42) -> 297.57 | AB42: =IF(Q42=0,"0",G42/Q42) -> 223.1775 | AC42: =IF(Z42="0","0",O42/Z42) -> 11.674246 | AD42: =IF(AA42="0","0",N42/AA42) -> 46.696984 | AE42: =IF(AB42="0","0",O42/AB42) -> 31.131323 | AF42: =IF(R42=0,"0",E42/R42) -> 0 | AG42: =IF(R42=0,"0",F42/R42) -> 0 | AH42: =IF(R42=0,"0",G42/R42) -> 0 | AI42: =IF(AF42="0","0",O42/AF42) -> 0 | AJ42: =IF(AG42="0","0",O42/AG42) -> 0 | AK42: =IF(AH42="0","0",N42/AH42) -> 0 | AL42: =T42+Z42+AF42 -> 595.14 | AM42: =U42+AA42+AG42 -> 297.57 | AN42: =V42+AB42+AH42 -> 223.1775 | AO42: =IF(I42="Strap","Tensile",IF(P42>0,"Tensile","Shear")) -> Shear | AP42: =IF(I42="Strap","Tensile",IF(Q42>0,"Tensile","Shear")) -> Tensile | AQ42: =IF(I42="Strap","Tensile",IF(R42>0,"Tensile","Shear")) -> Shear | AR42: =W42+AC42+AI42 -> 11.674246 | AS42: =X42+AD42+AJ42 -> 46.696984 | AT42: =Y42+AE42+AK42 -> 31.131323
...

Sheet Fastener Data
B2: Property Class | C2: Allowable Yield Stress (MPa) | E2: Bolt Size | F2: Minor Diameter Area (mm^2) | G2: Minor Diameter (mm)
B3: A2-70 | C3: 450 | E3: M1.6 | F3: 1.0762 | G3: =2*SQRT(F3/PI()) -> 1.1705812
B4: 4.6 | C4: 240 | E4: M2 | F4: 1.789 | G4: =2*SQRT(F4/PI()) -> 1.5092467
B5: 4.8 | C5: 340 | E5: M2.5 | F5: 2.9801 | G5: =2*SQRT(F5/PI()) -> 1.9479171
B6: 5.8 | C6: 420 | E6: M3 | F6: 4.4734 | G6: =2*SQRT(F6/PI()) -> 2.3865686
B7: 8.8 | C7: 640 | E7: M3.5 | F7: 5.9997 | G7: =2*SQRT(F7/PI()) -> 2.7638841
B8: 9.8 | C8: 720 | E8: M4 | F8: 7.7496 | G8: =2*SQRT(F8/PI()) -> 3.1411936
B9: 10.9 | C9: 940 | E9: M5 | F9: 12.683 | G9: =2*SQRT(F9/PI()) -> 4.0185193
B10: 12.9 | C10: 1100 | E10: M6 | F10: 17.894 | G10: =2*SQRT(F10/PI()) -> 4.7731906
B11: DRing | C11: 8896 | E11: M8 | F11: 32.841 | G11: =2*SQRT(F11/PI()) -> 6.4664101
B12: Locking Pin | C12: 250 | E12: M10 | F12: 52.292 | G12: =2*SQRT(F12/PI()) -> 8.1596717
B13: Ratchet (1.5") | C13: 30000 | E13: M12 | F13: 76.247 | G13: =2*SQRT(F13/PI()) -> 9.8529536
B14: Ratchet (1") | C14: 5000 | E14: M14 | F14: 104.71 | G14: =2*SQRT(F14/PI()) -> 11.546468
B15: Strap (Net) | C15: 3500 | E15: M16 | F15: 144.12 | G15: =2*SQRT(F15/PI()) -> 13.546191
B16: Spring Latch | C16: 165 | E16: M20 | F16: 225.19 | G16: =2*SQRT(F16/PI()) -> 16.932832
B17: Camlock Strap (1.5") | C17: 18000 | E17: M22* | F17: 281.53 | G17: =2*SQRT(F17/PI()) -> 18.932911
B18: Camlock Strap (1") | C18: 2500 | E18: M24 | F18: 324.27 | G18: =2*SQRT(F18/PI()) -> 20.319286
E19: M27* | F19: 427.09 | G19: =2*SQRT(F19/PI()) -> 23.31926
E20: M30 | F20: 518.99 | G20: =2*SQRT(F20/PI()) -> 25.706003
B21: Note: For non-bolt down (eg, Lashing & Dring) are in Newton | E21: M33 | F21: 647.19 | G21: =2*SQRT(F21/PI()) -> 28.705886
E22: M36 | F22: 759.28 | G22: =2*SQRT(F22/PI()) -> 31.092528
E23: 1/4-20 | F23: =PI()*G23^2/4 -> 21.711909 | G23: 5.2578
E24: Locking Pin | F24: =PI()*((G24/2)^2) -> 28.274334 | G24: 6
E25: Spring Latch | F25: =PI()*((G25/2)^2) -> 113.09734 | G25: 12
E26: Ratchet (1.5") | F26: 1 | G26: 1
E27: Ratchet (1") | F27: 1 | G27: 1
E28: Camlock Strap (1.5") | F28: 1 | G28: 1
E29: Camlock Strap (1") | F29: 1 | G29: 1
H30: 9.74mm

Sheet Tie-Down Provision Summary
B1: M2 Tie-Down Provision Summary
C3: Gravity Constant | D3: ='Tie-Down Provision Workings'!D3 -> 9.81 | E3: m/s^2
C4: Longitudinal Design Force | D4: ='Tie-Down Provision Workings'!D4 -> 4 | E4: G
C5: Vertical Design Force | D5: ='Tie-Down Provision Workings'!D5 -> 2 | E5: G
C6: Lateral Design Force | D6: ='Tie-Down Provision Workings'!D6 -> 1.5 | E6: G
E8: Ultimate Limit Load (N) | H8: Directly Fastened By
B9: No. | C9: Item | D9: Individual Weight (kg) | E9: Load Direction | F9: Loading Factor (G) | G9: Design Limit Load (N) | H9: Type of Fastener | I9: Qty Used Per Axis | J9: Force (N) | K9: Force Type | L9: Individual Force (N) | M9: Safety Factor
B10: 1 | C10: =VLOOKUP(B10,'Tie-Down Provision Workings'!$B$10:$AT$64,2,FALSE) -> Air-Con (IDU 1, 2) fastened to front wall | D10: =VLOOKUP(C10,'Tie-Down Provision Workings'!$C$10:$AT$64,2,FALSE) -> 14 | E10: Longitudinal | F10: =$D$4 -> 4 | G10: =VLOOKUP(C10,'Tie-Down Provision Workings'!$C$10:$AT$64,3,FALSE) -> 549.36 | H10: =VLOOKUP(C10,'Tie-Down Provision Workings'!$C$10:$AT$64,8,FALSE) -> M6 | I10: =VLOOKUP(C10,'Tie-Down Provision Workings'!$C$10:$AT$64,14,FALSE) -> 6 | J10: =IF(K10="Shear",VLOOKUP(C10,'Tie-Down Provision Workings'!$C$10:$AT$64,13,FALSE),VLOOKUP(C10,'Tie-Down Provision Workings'!$C$10:$AT$64,12,FALSE)) -> 11452.16 | K10: =VLOOKUP(C10,'Tie-Down Provision Workings'!$C$10:$AT$64,39,FALSE) -> Tensile | L10: =VLOOKUP(C10,'Tie-Down Provision Workings'!$C$10:$AT$64,36,FALSE) -> 91.56 | M10: =VLOOKUP(C10,'Tie-Down Provision Workings'!$C$10:$AT$64,42,FALSE) -> 125.0782
E11: Vertical | F11: =$D$5 -> 2 | G11: =VLOOKUP(C10,'Tie-Down Provision Workings'!$C$10:$AT$64,4,FALSE) -> 274.68 | I11: =VLOOKUP(C10,'Tie-Down Provision Workings'!$C$10:$AT$64,14,FALSE) -> 6 | J11: =IF(K11="Shear",VLOOKUP(C10,'Tie-Down Provision Workings'!$C$10:$AT$64,13,FALSE),VLOOKUP(C10,'Tie-Down Provision Workings'!$C$10:$AT$64,12,FALSE)) -> 5726.08 | K11: =VLOOKUP(C10,'Tie-Down Provision Workings'!$C$10:$AT$64,40,FALSE) -> Shear | L11: =VLOOKUP(C10,'Tie-Down Provision Workings'!$C$10:$AT$64,37,FALSE) -> 45.78 | M11: =VLOOKUP(C10,'Tie-Down Provision Workings'!$C$10:$AT$64,43,FALSE) -> 125.0782
E12: Lateral | F12: =$D$6 -> 1.5 | G12: =VLOOKUP(C10,'Tie-Down Provision Workings'!$C$10:$AT$64,5,FALSE) -> 206.01 | I12: =VLOOKUP(C10,'Tie-Down Provision Workings'!$C$10:$AT$64,16,FALSE) -> 0 | J12: =IF(K12="Shear",VLOOKUP(C10,'Tie-Down Provision Workings'!$C$10:$AT$64,13,FALSE),VLOOKUP(C10,'Tie-Down Provision Workings'!$C$10:$AT$64,12,FALSE)) -> 5726.08 | K12: =VLOOKUP(C10,'Tie-Down Provision Workings'!$C$10:$AT$64,41,FALSE) -> Shear | L12: =VLOOKUP(C10,'Tie-Down Provision Workings'!$C$10:$AT$64,38,FALSE) -> 34.335 | M12: =VLOOKUP(C10,'Tie-Down Provision Workings'!$C$10:$AT$64,44,FALSE) -> 166.77093
